[2025-10-31T23:10:52.095+0700] {local_task_job_runner.py:120} INFO - ::group::Pre task execution logs
[2025-10-31T23:10:52.112+0700] {taskinstance.py:2073} INFO - Dependencies all met for dep_context=non-requeueable deps ti=<TaskInstance: vehicle_pipeline_new_dag.start_vehicle_consumer scheduled__2025-10-31T15:00:00+00:00 [queued]>
[2025-10-31T23:10:52.116+0700] {taskinstance.py:2073} INFO - Dependencies all met for dep_context=requeueable deps ti=<TaskInstance: vehicle_pipeline_new_dag.start_vehicle_consumer scheduled__2025-10-31T15:00:00+00:00 [queued]>
[2025-10-31T23:10:52.116+0700] {taskinstance.py:2303} INFO - Starting attempt 4 of 6
[2025-10-31T23:10:52.123+0700] {taskinstance.py:2327} INFO - Executing <Task(BashOperator): start_vehicle_consumer> on 2025-10-31 15:00:00+00:00
[2025-10-31T23:10:52.129+0700] {warnings.py:110} WARNING - /home/***/.local/lib/python3.12/site-packages/***/task/task_runner/standard_task_runner.py:61: DeprecationWarning: This process (pid=2212) is multi-threaded, use of fork() may lead to deadlocks in the child.
  pid = os.fork()

[2025-10-31T23:10:52.130+0700] {standard_task_runner.py:63} INFO - Started process 2214 to run task
[2025-10-31T23:10:52.131+0700] {standard_task_runner.py:90} INFO - Running: ['***', 'tasks', 'run', 'vehicle_pipeline_new_dag', 'start_vehicle_consumer', 'scheduled__2025-10-31T15:00:00+00:00', '--job-id', '432', '--raw', '--subdir', 'DAGS_FOLDER/vehicel_pipeline_new_dag.py', '--cfg-path', '/tmp/tmp6nq9rubo']
[2025-10-31T23:10:52.133+0700] {standard_task_runner.py:91} INFO - Job 432: Subtask start_vehicle_consumer
[2025-10-31T23:10:52.174+0700] {task_command.py:426} INFO - Running <TaskInstance: vehicle_pipeline_new_dag.start_vehicle_consumer scheduled__2025-10-31T15:00:00+00:00 [running]> on host f7bb1ad77e89
[2025-10-31T23:10:52.237+0700] {taskinstance.py:2644} INFO - Exporting env vars: AIRFLOW_CTX_DAG_OWNER='***' AIRFLOW_CTX_DAG_ID='vehicle_pipeline_new_dag' AIRFLOW_CTX_TASK_ID='start_vehicle_consumer' AIRFLOW_CTX_EXECUTION_DATE='2025-10-31T15:00:00+00:00' AIRFLOW_CTX_TRY_NUMBER='4' AIRFLOW_CTX_DAG_RUN_ID='scheduled__2025-10-31T15:00:00+00:00'
[2025-10-31T23:10:52.239+0700] {taskinstance.py:430} INFO - ::endgroup::
[2025-10-31T23:10:52.239+0700] {subprocess.py:63} INFO - Tmp dir root location: /tmp
[2025-10-31T23:10:52.240+0700] {subprocess.py:75} INFO - Running command: ['/usr/bin/bash', '-c', 'bash -c "timeout 45m /opt/***/projects/vehicle_count/scripts/run_consumer.sh"']
[2025-10-31T23:10:52.249+0700] {subprocess.py:86} INFO - Output:
[2025-10-31T23:10:52.255+0700] {subprocess.py:93} INFO - timeout: failed to run command ‘/opt/***/projects/vehicle_count/scripts/run_consumer.sh’: Permission denied
[2025-10-31T23:10:52.255+0700] {subprocess.py:97} INFO - Command exited with return code 126
[2025-10-31T23:10:52.256+0700] {taskinstance.py:441} INFO - ::group::Post task execution logs
[2025-10-31T23:10:52.266+0700] {taskinstance.py:2890} ERROR - Task failed with exception
Traceback (most recent call last):
  File "/home/airflow/.local/lib/python3.12/site-packages/airflow/models/taskinstance.py", line 460, in _execute_task
    result = _execute_callable(context=context, **execute_callable_kwargs)
             ^^^^^^^^^^^^^^^^^^^^^^^^^^^^^^^^^^^^^^^^^^^^^^^^^^^^^^^^^^^^^
  File "/home/airflow/.local/lib/python3.12/site-packages/airflow/models/taskinstance.py", line 432, in _execute_callable
    return execute_callable(context=context, **execute_callable_kwargs)
           ^^^^^^^^^^^^^^^^^^^^^^^^^^^^^^^^^^^^^^^^^^^^^^^^^^^^^^^^^^^^
  File "/home/airflow/.local/lib/python3.12/site-packages/airflow/models/baseoperator.py", line 400, in wrapper
    return func(self, *args, **kwargs)
           ^^^^^^^^^^^^^^^^^^^^^^^^^^^
  File "/home/airflow/.local/lib/python3.12/site-packages/airflow/operators/bash.py", line 243, in execute
    raise AirflowException(
airflow.exceptions.AirflowException: Bash command failed. The command returned a non-zero exit code 126.
[2025-10-31T23:10:52.269+0700] {taskinstance.py:1205} INFO - Marking task as UP_FOR_RETRY. dag_id=vehicle_pipeline_new_dag, task_id=start_vehicle_consumer, execution_date=20251031T150000, start_date=20251031T161052, end_date=20251031T161052
[2025-10-31T23:10:52.277+0700] {standard_task_runner.py:110} ERROR - Failed to execute job 432 for task start_vehicle_consumer (Bash command failed. The command returned a non-zero exit code 126.; 2214)
[2025-10-31T23:10:52.305+0700] {local_task_job_runner.py:240} INFO - Task exited with return code 1
[2025-10-31T23:10:52.322+0700] {taskinstance.py:3482} INFO - 0 downstream tasks scheduled from follow-on schedule check
[2025-10-31T23:10:52.323+0700] {local_task_job_runner.py:222} INFO - ::endgroup::
